Workbook
Name micro_2022_10_04_f0001: compiled!$A$1:$AI$1075
Name micro_2022_10_04_f0001: 'f0001'!$A$1:$AI$1076
Name micro_2022_10_04_f0002: compiled!$A$1076:$AI$1307
Name micro_2022_10_04_f0002: 'f0002'!$A$1:$AI$234
Name micro_2022_10_04_f0003: compiled!$A$1308:$AI$1623
Name micro_2022_10_04_f0003: 'f0003'!$A$1:$AI$318
Name micro_2022_10_04_f0004: compiled!$A$1624:$AI$1674
Name micro_2022_10_04_f0004: 'f0004'!$A$1:$AI$53

Sheet f0001
A1: SN:3K60180500001585 BD:Jul 23 2018 VC:834b9c1 MD5:48f99e4865ed8b810be1bb0eaaabf929
A2: SysTime | B2: Time | C2: Batt_v | D2: Batt_v_sd | E2: BATT_PERCENT | F2: BATT_PERCENT_sd | G2: [CH4]_ppm | H2: [CH4]_ppm_sd | I2: [H2O]_ppm | J2: [H2O]_ppm_sd | K2: [H2Oa]_ppm | L2: [H2Oa]_ppm_sd | M2: [CO2]_ppm | N2: [CO2]_ppm_sd | O2: [CH4]d_ppm | P2: [CH4]d_ppm_sd | Q2: [CO2]d_ppm | R2: [CO2]d_ppm_sd | S2: GasP_torr | T2: GasP_torr_sd | U2: GasT_C | V2: GasT_C_sd | W2: AmbT_C | X2: AmbT_C_sd | Y2: RD0_us | Z2: RD0_us_sd | AA2: RD1_us | AB2: RD1_us_sd | AC2: Temp_Status_mA | AD2: Temp_Status_mA_sd | AE2: Analyzer_Status_mA | AF2: Analyzer_Status_mA_sd | AG2: Fit_Flag | AH2: MIU_VALVE | AI2: MIU_DESC
A3: 44838.429 | B3: 10/04/2022 10:18:11.622 | C3: 3.63513 | D3: 0 | E3: 43.4824 | F3: 0 | G3: 1.92229 | H3: 0 | I3: 2228.77 | J3: 0 | K3: 10547.4 | L3: 0 | M3: 853.118 | N3: 0 | O3: 0.963294 | P3: 0 | Q3: 427.512 | R3: 0 | S3: 507.76 | T3: 0 | U3: 14.168 | V3: 0 | W3: 17.0334 | X3: 0 | Y3: 3.72377 | Z3: 0 | AA3: 3.03796 | AB3: 0 | AC3: 20 | AD3: 0 | AE3: 17 | AF3: 0 | AG3: 2 | AH3: -1 | AI3: Disabled
A4: 44838.429 | B4: 10/04/2022 10:18:16.595 | C4: 3.63941 | D4: 0.00106904 | E4: 87.0673 | F4: 0.0255751 | G4: 1.92058 | H4: 0.00266303 | I4: 2783.01 | J4: 840.282 | K4: 10746.3 | L4: 228.149 | M4: 857.07 | N4: 1.94216 | O4: 1.92593 | P4: 0.00211667 | Q4: 859.463 | R4: 2.60082 | S4: 507.743 | T4: 0.0307744 | U4: 14.1648 | V4: 0.00286805 | W4: 17.0356 | X4: 0.0160398 | Y4: 3.72452 | Z4: 0.00112189 | AA4: 3.03786 | AB4: 0.000416981 | AC4: 20 | AD4: 0 | AE4: 17 | AF4: 0 | AG4: 2 | AH4: -1 | AI4: Disabled
A5: 44838.429 | B5: 10/04/2022 10:18:21.568 | C5: 3.63857 | D5: 0.00146066 | E5: 87.0472 | F5: 0.0349439 | G5: 1.92438 | H5: 0.00363289 | I5: 4235.19 | J5: 394.818 | K5: 10630.9 | L5: 303.018 | M5: 864.461 | N5: 1.4234 | O5: 1.93257 | P5: 0.00421924 | Q5: 868.138 | R5: 1.70147 | S5: 507.753 | T5: 0.0299492 | U5: 14.1589 | V5: 0.000770588 | W5: 17.0572 | X5: 0.010957 | Y5: 3.72385 | Z5: 0.000199009 | AA5: 3.0371 | AB5: 0.000371263 | AC5: 20 | AD5: 0 | AE5: 17 | AF5: 0 | AG5: 2 | AH5: -1 | AI5: Disabled
A6: 44838.429 | B6: 10/04/2022 10:18:26.541 | C6: 3.63676 | D6: 0.00132289 | E6: 87.0038 | F6: 0.031648 | G6: 1.92415 | H6: 0.00127904 | I6: 6036.46 | J6: 552.958 | K6: 10676.3 | L6: 214.891 | M6: 866.922 | N6: 1.48574 | O6: 1.93584 | P6: 0.00209683 | Q6: 872.188 | R6: 1.96634 | S6: 507.761 | T6: 0.0144471 | U6: 14.1607 | V6: 0.0033516 | W6: 17.0785 | X6: 0.0365115 | Y6: 3.72341 | Z6: 0.000548593 | AA6: 3.03748 | AB6: 0.000385639 | AC6: 20 | AD6: 0 | AE6: 17 | AF6: 0 | AG6: 3 | AH6: -1 | AI6: Disabled
A7: 44838.43 | B7: 10/04/2022 10:18:31.521 | C7: 3.63597 | D7: 0.00130819 | E7: 86.985 | F7: 0.0312964 | G7: 1.92501 | H7: 0.00204844 | I7: 6358.62 | J7: 406.111 | K7: 10681.8 | L7: 239.541 | M7: 869.778 | N7: 1.04667 | O7: 1.93733 | P7: 0.00193323 | Q7: 875.344 | R7: 1.17485 | S7: 507.724 | T7: 0.0548227 | U7: 14.1609 | V7: 0.0050294 | W7: 17.091 | X7: 0.023571 | Y7: 3.72337 | Z7: 0.000316757 | AA7: 3.03693 | AB7: 0.000504146 | AC7: 20 | AD7: 0 | AE7: 17 | AF7: 0 | AG7: 3 | AH7: -1 | AI7: Disabled
A8: 44838.43 | B8: 10/04/2022 10:18:36.493 | C8: 3.63382 | D8: 0.00113742 | E8: 86.9336 | F8: 0.027211 | G8: 1.92714 | H8: 0.00406584 | I8: 7308.31 | J8: 560.576 | K8: 10766.1 | L8: 463.851 | M8: 871.364 | N8: 1.28276 | O8: 1.94133 | P8: 0.00431501 | Q8: 877.779 | R8: 1.2954 | S8: 507.752 | T8: 0.0437165 | U8: 14.1672 | V8: 0.010284 | W8: 17.1268 | X8: 0.0191142 | Y8: 3.72316 | Z8: 0.000497983 | AA8: 3.0371 | AB8: 0.000264914 | AC8: 20 | AD8: 0 | AE8: 17 | AF8: 0 | AG8: 3 | AH8: -1 | AI8: Disabled
A9: 44838.43 | B9: 10/04/2022 10:18:41.465 | C9: 3.63359 | D9: 0.000495247 | E9: 86.9279 | F9: 0.011848 | G9: 1.93063 | H9: 0.00237245 | I9: 7606.09 | J9: 662.809 | K9: 10860.2 | L9: 425.22 | M9: 874.826 | N9: 1.13524 | O9: 1.94542 | P9: 0.00291319 | Q9: 881.532 | R9: 1.54726 | S9: 507.733 | T9: 0.0548648 | U9: 14.1605 | V9: 0.00882173 | W9: 17.1575 | X9: 0.0272332 | Y9: 3.72195 | Z9: 0.000682863 | AA9: 3.03681 | AB9: 0.000463218 | AC9: 20 | AD9: 0 | AE9: 17 | AF9: 0 | AG9: 3 | AH9: -1 | AI9: Disabled
A10: 44838.43 | B10: 10/04/2022 10:18:46.439 | C10: 3.63289 | D10: 0.00144015 | E10: 86.9112 | F10: 0.0344534 | G10: 1.93041 | H10: 0.00320161 | I10: 7791.87 | J10: 328.108 | K10: 10690.2 | L10: 119.668 | M10: 876.026 | N10: 1.09157 | O10: 1.94557 | P10: 0.00366442 | Q10: 882.905 | R10: 1.20193 | S10: 507.713 | T10: 0.0453368 | U10: 14.1541 | V10: 0.0087883 | W10: 17.1833 | X10: 0.0237966 | Y10: 3.72219 | Z10: 0.000472232 | AA10: 3.03685 | AB10: 0.000822044 | AC10: 20 | AD10: 0 | AE10: 17 | AF10: 0 | AG10: 3 | AH10: -1 | AI10: Disabled
A11: 44838.43 | B11: 10/04/2022 10:18:51.411 | C11: 3.63246 | D11: 0.00121149 | E11: 86.9011 | F11: 0.0289831 | G11: 1.93211 | H11: 0.00347416 | I11: 8235.83 | J11: 320.516 | K11: 10842.5 | L11: 300.381 | M11: 877.786 | N11: 1.0734 | O11: 1.94815 | P11: 0.00319571 | Q11: 885.076 | R11: 1.14028 | S11: 507.697 | T11: 0.049449 | U11: 14.1462 | V11: 0.00232943 | W11: 17.1899 | X11: 0.0296315 | Y11: 3.72199 | Z11: 0.00041535 | AA11: 3.03713 | AB11: 0.000466585 | AC11: 20 | AD11: 0 | AE11: 17 | AF11: 0 | AG11: 3 | AH11: -1 | AI11: Disabled
A12: 44838.43 | B12: 10/04/2022 10:18:56.383 | C12: 3.63086 | D12: 0.00167617 | E12: 86.8626 | F12: 0.0400997 | G12: 1.93231 | H12: 0.00234679 | I12: 8255.07 | J12: 343.526 | K12: 10773.2 | L12: 427.128 | M12: 878.917 | N12: 0.90498 | O12: 1.94839 | P12: 0.00268241 | Q12: 886.233 | R12: 0.837941 | S12: 507.697 | T12: 0.0450291 | U12: 14.148 | V12: 0.00382317 | W12: 17.2085 | X12: 0.0227274 | Y12: 3.7218 | Z12: 0.000549135 | AA12: 3.03647 | AB12: 0.000524441 | AC12: 20 | AD12: 0 | AE12: 17 | AF12: 0 | AG12: 3 | AH12: -1 | AI12: Disabled
A13: 44838.43 | B13: 10/04/2022 10:19:01.357 | C13: 3.63049 | D13: 0.00118681 | E13: 86.8539 | F13: 0.0283925 | G13: 1.93253 | H13: 0.00508014 | I13: 8866.29 | J13: 359.701 | K13: 11036.5 | L13: 462.107 | M13: 878.826 | N13: 2.04374 | O13: 1.94982 | P13: 0.00572616 | Q13: 886.688 | R13: 2.13249 | S13: 507.678 | T13: 0.056018 | U13: 14.1473 | V13: 0.00422216 | W13: 17.2346 | X13: 0.0224957 | Y13: 3.72097 | Z13: 0.000747112 | AA13: 3.03584 | AB13: 0.000432972 | AC13: 20 | AD13: 0 | AE13: 17 | AF13: 0 | AG13: 3 | AH13: -1 | AI13: Disabled
A14: 44838.43 | B14: 10/04/2022 10:19:06.328 | C14: 3.62779 | D14: 0.00514383 | E14: 86.7892 | F14: 0.123058 | G14: 1.93215 | H14: 0.00555321 | I14: 8992.94 | J14: 335.598 | K14: 11061.5 | L14: 266.161 | M14: 881.066 | N14: 2.35577 | O14: 1.94968 | P14: 0.0054212 | Q14: 889.061 | R14: 2.29677 | S14: 507.642 | T14: 0.06755 | U14: 14.1426 | V14: 0.00189531 | W14: 17.2468 | X14: 0.0287507 | Y14: 3.72145 | Z14: 0.000603824 | AA14: 3.03621 | AB14: 0.000406385 | AC14: 20 | AD14: 0 | AE14: 10.6 | AF14: 3.57771 | AG14: 3 | AH14: -1 | AI14: Disabled
... A1076: 44838.491 | B1076: 10/04/2022 11:47:07.893 | C1076: 2.90092 | D1076: 0.00392502 | E1076: 69.4 | F1076: 0.0939 | G1076: 1.988 | H1076: 0.00300572 | I1076: 11442.7 | J1076: 191.363 | K1076: 14030.3 | L1076: 46.0614 | M1076: 642.151 | N1076: 0.88048 | O1076: 2.01101 | P1076: 0.00298001 | Q1076: 649.584 | R1076: 0.887508 | S1076: 506.786 | T1076: 0.0721745 | U1076: 24.4011 | V1076: 0.00150436 | W1076: 29.0026 | X1076: 0.0349908 | Y1076: 3.72421 | Z1076: 0.000419161 | AA1076: 3.0305 | AB1076: 0.00041661 | AC1076: 20 | AD1076: 0 | AE1076: 9 | AF1076: 0 | AG1076: 3 | AH1076: -1 | AI1076: Disabled

Sheet f0002
A1: SN:3K60180500001585 BD:Jul 23 2018 VC:834b9c1 MD5:48f99e4865ed8b810be1bb0eaaabf929
A2: SysTime | B2: Time | C2: Batt_v | D2: Batt_v_sd | E2: BATT_PERCENT | F2: BATT_PERCENT_sd | G2: [CH4]_ppm | H2: [CH4]_ppm_sd | I2: [H2O]_ppm | J2: [H2O]_ppm_sd | K2: [H2Oa]_ppm | L2: [H2Oa]_ppm_sd | M2: [CO2]_ppm | N2: [CO2]_ppm_sd | O2: [CH4]d_ppm | P2: [CH4]d_ppm_sd | Q2: [CO2]d_ppm | R2: [CO2]d_ppm_sd | S2: GasP_torr | T2: GasP_torr_sd | U2: GasT_C | V2: GasT_C_sd | W2: AmbT_C | X2: AmbT_C_sd | Y2: RD0_us | Z2: RD0_us_sd | AA2: RD1_us | AB2: RD1_us_sd | AC2: Temp_Status_mA | AD2: Temp_Status_mA_sd | AE2: Analyzer_Status_mA | AF2: Analyzer_Status_mA_sd | AG2: Fit_Flag | AH2: MIU_VALVE | AI2: MIU_DESC
A3: 44838.522 | B3: 10/04/2022 12:31:06.595 | C3: 4.00643 | D3: 0 | E3: 47.9237 | F3: 0 | G3: 1.9721 | H3: 0 | I3: 4147.67 | J3: 0 | K3: 13407.3 | L3: 0 | M3: 675.401 | N3: 0 | O3: 0.990157 | P3: 0 | Q3: 339.107 | R3: 0 | S3: 507.226 | T3: 0 | U3: 22.2654 | V3: 0 | W3: 25.5574 | X3: 0 | Y3: 3.72412 | Z3: 0 | AA3: 3.03528 | AB3: 0 | AC3: 20 | AD3: 0 | AE3: 17 | AF3: 0 | AG3: 2 | AH3: -1 | AI3: Disabled
A4: 44838.522 | B4: 10/04/2022 12:31:11.568 | C4: 4.00641 | D4: 0.000575033 | E4: 95.847 | F4: 0.0137568 | G4: 1.97129 | H4: 0.00404979 | I4: 5355.32 | J4: 428.575 | K4: 13628 | L4: 165.268 | M4: 659.862 | N4: 12.8291 | O4: 1.9819 | P4: 0.00335037 | Q4: 663.41 | R4: 12.6319 | S4: 507.248 | T4: 0.0223115 | U4: 22.2797 | V4: 0.00784264 | W4: 25.5146 | X4: 0.0323211 | Y4: 3.72356 | Z4: 0.00074176 | AA4: 3.03549 | AB4: 0.000450878 | AC4: 20 | AD4: 0 | AE4: 17 | AF4: 0 | AG4: 2 | AH4: -1 | AI4: Disabled
A5: 44838.522 | B5: 10/04/2022 12:31:16.540 | C5: 4.00626 | D5: 0.000439846 | E5: 95.8435 | F5: 0.0105226 | G5: 1.96557 | H5: 0.0034193 | I5: 6740.4 | J5: 523.315 | K5: 13663.6 | L5: 163.661 | M5: 640.423 | N5: 1.35239 | O5: 1.97891 | P5: 0.0040183 | Q5: 644.769 | R5: 1.67405 | S5: 507.246 | T5: 0.0147589 | U5: 22.2784 | V5: 0.0135511 | W5: 25.4549 | X5: 0.0413968 | Y5: 3.72347 | Z5: 0.000616451 | AA5: 3.03572 | AB5: 0.00059814 | AC5: 20 | AD5: 0 | AE5: 17 | AF5: 0 | AG5: 2 | AH5: -1 | AI5: Disabled
A6: 44838.522 | B6: 10/04/2022 12:31:21.513 | C6: 4.00681 | D6: 0.000115962 | E6: 95.8568 | F6: 0.00277422 | G6: 1.96794 | H6: 0.00580385 | I6: 6813.64 | J6: 272.621 | K6: 13790.2 | L6: 130.95 | M6: 639.848 | N6: 2.55731 | O6: 1.98144 | P6: 0.00595792 | Q6: 644.238 | R6: 2.67902 | S6: 507.238 | T6: 0.0514181 | U6: 22.2899 | V6: 0.0217023 | W6: 25.4326 | X6: 0.0204773 | Y6: 3.72267 | Z6: 0.00042554 | AA6: 3.03664 | AB6: 0.000363347 | AC6: 20 | AD6: 0 | AE6: 17 | AF6: 0 | AG6: 3 | AH6: -1 | AI6: Disabled
A7: 44838.522 | B7: 10/04/2022 12:31:26.486 | C7: 4.00735 | D7: 0.000572534 | E7: 95.8697 | F7: 0.013697 | G7: 1.965 | H7: 0.00586183 | I7: 7397.45 | J7: 229.768 | K7: 13797.2 | L7: 149.978 | M7: 631.519 | N7: 11.4291 | O7: 1.97965 | P7: 0.00554192 | Q7: 636.223 | R7: 11.3836 | S7: 507.235 | T7: 0.0102928 | U7: 22.3518 | V7: 0.0523107 | W7: 25.407 | X7: 0.014269 | Y7: 3.72285 | Z7: 0.000437132 | AA7: 3.03736 | AB7: 0.000246576 | AC7: 20 | AD7: 0 | AE7: 17 | AF7: 0 | AG7: 3 | AH7: -1 | AI7: Disabled
A8: 44838.522 | B8: 10/04/2022 12:31:31.458 | C8: 4.00788 | D8: 0.000285201 | E8: 95.8822 | F8: 0.00682299 | G8: 1.96023 | H8: 0.00384186 | I8: 8680.12 | J8: 867.27 | K8: 13765.5 | L8: 111.22 | M8: 611.953 | N8: 3.30473 | O8: 1.97739 | P8: 0.00511142 | Q8: 617.31 | R8: 2.93626 | S8: 507.214 | T8: 0.0152444 | U8: 22.291 | V8: 0.0215333 | W8: 25.4175 | X8: 0.0217975 | Y8: 3.72255 | Z8: 0.000803886 | AA8: 3.03802 | AB8: 0.000364284 | AC8: 20 | AD8: 0 | AE8: 17 | AF8: 0 | AG8: 3 | AH8: -1 | AI8: Disabled
A9: 44838.522 | B9: 10/04/2022 12:31:36.431 | C9: 4.0084 | D9: 0.000400571 | E9: 95.8947 | F9: 0.00958304 | G9: 1.96024 | H9: 0.0037591 | I9: 9994.07 | J9: 69.4719 | K9: 14012 | L9: 158.552 | M9: 606.915 | N9: 5.07975 | O9: 1.98003 | P9: 0.00385212 | Q9: 613.042 | R9: 5.13322 | S9: 507.207 | T9: 0.0301145 | U9: 22.2718 | V9: 0.0261249 | W9: 25.3752 | X9: 0.0357948 | Y9: 3.72189 | Z9: 0.000307303 | AA9: 3.03882 | AB9: 0.000547363 | AC9: 20 | AD9: 0 | AE9: 17 | AF9: 0 | AG9: 3 | AH9: -1 | AI9: Disabled
A10: 44838.522 | B10: 10/04/2022 12:31:41.405 | C10: 4.00896 | D10: 0.00046449 | E10: 95.9082 | F10: 0.0111122 | G10: 1.96209 | H10: 0.00108224 | I10: 10457.1 | J10: 180.775 | K10: 13947 | L10: 70.9628 | M10: 588.163 | N10: 50.4667 | O10: 1.98283 | P10: 0.000826048 | Q10: 594.38 | R10: 51.0178 | S10: 507.216 | T10: 0.0521317 | U10: 22.2756 | V10: 0.011347 | W10: 25.3464 | X10: 0.0345558 | Y10: 3.72239 | Z10: 0.000401072 | AA10: 3.03881 | AB10: 0.00120733 | AC10: 20 | AD10: 0 | AE10: 16 | AF10: 2.23607 | AG10: 3 | AH10: -1 | AI10: Disabled
A11: 44838.522 | B11: 10/04/2022 12:31:46.377 | C11: 4.00986 | D11: 0.000382588 | E11: 95.9296 | F11: 0.00915283 | G11: 1.95757 | H11: 0.00207465 | I11: 10825.7 | J11: 138.583 | K11: 14100.7 | L11: 119.327 | M11: 599.203 | N11: 4.92444 | O11: 1.97899 | P11: 0.00200225 | Q11: 605.76 | R11: 4.95838 | S11: 507.195 | T11: 0.0288489 | U11: 22.2729 | V11: 0.0154681 | W11: 25.3241 | X11: 0.0102516 | Y11: 3.72257 | Z11: 0.000499206 | AA11: 3.03649 | AB11: 0.000889097 | AC11: 20 | AD11: 0 | AE11: 17 | AF11: 0 | AG11: 3 | AH11: -1 | AI11: Disabled
A12: 44838.522 | B12: 10/04/2022 12:31:51.349 | C12: 4.01033 | D12: 0.000173573 | E12: 95.9409 | F12: 0.00415247 | G12: 1.957 | H12: 0.00372387 | I12: 10912.1 | J12: 146.91 | K12: 13896.1 | L12: 104.23 | M12: 587.076 | N12: 5.57961 | O12: 1.97859 | P12: 0.00394242 | Q12: 593.553 | R12: 5.60646 | S12: 507.202 | T12: 0.0099218 | U12: 22.2756 | V12: 0.00975674 | W12: 25.2866 | X12: 0.0148625 | Y12: 3.72174 | Z12: 0.000401322 | AA12: 3.03611 | AB12: 0.00036562 | AC12: 20 | AD12: 0 | AE12: 17 | AF12: 0 | AG12: 3 | AH12: -1 | AI12: Disabled
A13: 44838.522 | B13: 10/04/2022 12:31:56.322 | C13: 4.01092 | D13: 0.000323561 | E13: 95.9549 | F13: 0.00774069 | G13: 1.95228 | H13: 0.0042566 | I13: 11053.7 | J13: 193.869 | K13: 13899.4 | L13: 126.018 | M13: 571.738 | N13: 3.64601 | O13: 1.9741 | P13: 0.00453561 | Q13: 578.129 | R13: 3.72622 | S13: 507.21 | T13: 0.025135 | U13: 22.2613 | V13: 0.0132239 | W13: 25.2493 | X13: 0.0172445 | Y13: 3.72159 | Z13: 0.000466312 | AA13: 3.03563 | AB13: 0.000344367 | AC13: 20 | AD13: 0 | AE13: 17 | AF13: 0 | AG13: 3 | AH13: -1 | AI13: Disabled
A14: 44838.522 | B14: 10/04/2022 12:32:01.296 | C14: 4.01213 | D14: 0.000389943 | E14: 95.9839 | F14: 0.00932877 | G14: 1.95212 | H14: 0.00266954 | I14: 11351.6 | J14: 84.4299 | K14: 13896.6 | L14: 30.315 | M14: 573.279 | N14: 0.997444 | O14: 1.97454 | P14: 0.00274191 | Q14: 579.862 | R14: 1.02928 | S14: 507.202 | T14: 0.0165256 | U14: 22.2585 | V14: 0.0139235 | W14: 25.2405 | X14: 0.00785302 | Y14: 3.72212 | Z14: 0.000420519 | AA14: 3.03532 | AB14: 0.000462221 | AC14: 20 | AD14: 0 | AE14: 17 | AF14: 0 | AG14: 3 | AH14: -1 | AI14: Disabled
... A234: 44838.535 | B234: 10/04/2022 12:50:15.342 | C234: 4.053 | D234: 0.00306498 | E234: 96.9617 | F234: 0.0733249 | G234: 1.91699 | H234: 0.00180498 | I234: 11657.5 | J234: 202.626 | K234: 14551.6 | L234: 252.238 | M234: 545.367 | N234: 0.818576 | O234: 1.9396 | P234: 0.00172872 | Q234: 551.8 | R234: 0.864294 | S234: 506.869 | T234: 0.0390279 | U234: 22.093 | V234: 0.000678002 | W234: 25.8944 | X234: 0.0343824 | Y234: 3.71879 | Z234: 0.00017988 | AA234: 3.03449 | AB234: 0.00034287 | AC234: 20 | AD234: 0 | AE234: 17 | AF234: 0 | AG234: 3 | AH234: -1 | AI234: Disabled

Sheet f0003
A1: SN:3K60180500001585 BD:Jul 23 2018 VC:834b9c1 MD5:48f99e4865ed8b810be1bb0eaaabf929
A2: SysTime | B2: Time | C2: Batt_v | D2: Batt_v_sd | E2: BATT_PERCENT | F2: BATT_PERCENT_sd | G2: [CH4]_ppm | H2: [CH4]_ppm_sd | I2: [H2O]_ppm | J2: [H2O]_ppm_sd | K2: [H2Oa]_ppm | L2: [H2Oa]_ppm_sd | M2: [CO2]_ppm | N2: [CO2]_ppm_sd | O2: [CH4]d_ppm | P2: [CH4]d_ppm_sd | Q2: [CO2]d_ppm | R2: [CO2]d_ppm_sd | S2: GasP_torr | T2: GasP_torr_sd | U2: GasT_C | V2: GasT_C_sd | W2: AmbT_C | X2: AmbT_C_sd | Y2: RD0_us | Z2: RD0_us_sd | AA2: RD1_us | AB2: RD1_us_sd | AC2: Temp_Status_mA | AD2: Temp_Status_mA_sd | AE2: Analyzer_Status_mA | AF2: Analyzer_Status_mA_sd | AG2: Fit_Flag | AH2: MIU_VALVE | AI2: MIU_DESC
A3: 44838.536 | B3: 10/04/2022 12:51:49.988 | C3: 4.07067 | D3: 0 | E3: 48.6923 | F3: 0 | G3: 1.90527 | H3: 0 | I3: 4114.43 | J3: 0 | K3: 13856.7 | L3: 0 | M3: 586.333 | N3: 0 | O3: 0.956573 | P3: 0 | Q3: 294.378 | R3: 0 | S3: 506.838 | T3: 0 | U3: 22.1306 | V3: 0 | W3: 26.3872 | X3: 0 | Y3: 3.72318 | Z3: 0 | AA3: 3.03546 | AB3: 0 | AC3: 20 | AD3: 0 | AE3: 17 | AF3: 0 | AG3: 2 | AH3: -1 | AI3: Disabled
A4: 44838.536 | B4: 10/04/2022 12:51:54.961 | C4: 4.07127 | D4: 0.000628245 | E4: 97.3987 | F4: 0.0150298 | G4: 1.90786 | H4: 0.0009882 | I4: 4908.57 | J4: 615.402 | K4: 13980.9 | L4: 154.469 | M4: 590.807 | N4: 2.16887 | O4: 1.91727 | P4: 0.00195214 | Q4: 593.722 | R4: 2.48502 | S4: 506.855 | T4: 0.0129516 | U4: 22.1378 | V4: 0.00438077 | W4: 26.3978 | X4: 0.0285659 | Y4: 3.72319 | Z4: 0.000396505 | AA4: 3.03534 | AB4: 0.000386872 | AC4: 20 | AD4: 0 | AE4: 17 | AF4: 0 | AG4: 2 | AH4: -1 | AI4: Disabled
A5: 44838.536 | B5: 10/04/2022 12:51:59.934 | C5: 4.067 | D5: 0.00340773 | E5: 97.2966 | F5: 0.0815247 | G5: 1.90866 | H5: 0.0020972 | I5: 6414.47 | J5: 353.829 | K5: 14220.2 | L5: 121.52 | M5: 595.091 | N5: 1.6379 | O5: 1.92098 | P5: 0.00242544 | Q5: 598.933 | R5: 1.82981 | S5: 506.881 | T5: 0.0233016 | U5: 22.1315 | V5: 0.00612462 | W5: 26.4044 | X5: 0.0212478 | Y5: 3.72188 | Z5: 0.000630974 | AA5: 3.03511 | AB5: 0.000220193 | AC5: 20 | AD5: 0 | AE5: 17 | AF5: 0 | AG5: 2 | AH5: -1 | AI5: Disabled
A6: 44838.536 | B6: 10/04/2022 12:52:04.907 | C6: 4.06657 | D6: 0.00126104 | E6: 97.2864 | F6: 0.0301684 | G6: 1.90993 | H6: 0.00130198 | I6: 8199.2 | J6: 167.953 | K6: 14150.8 | L6: 106.695 | M6: 599.279 | N6: 0.913359 | O6: 1.92571 | P6: 0.00147467 | Q6: 604.233 | R6: 0.844491 | S6: 506.881 | T6: 0.038983 | U6: 22.1364 | V6: 0.0123503 | W6: 26.4282 | X6: 0.0115025 | Y6: 3.72234 | Z6: 0.000359317 | AA6: 3.03492 | AB6: 0.00022254 | AC6: 20 | AD6: 0 | AE6: 17 | AF6: 0 | AG6: 3 | AH6: -1 | AI6: Disabled
A7: 44838.536 | B7: 10/04/2022 12:52:09.879 | C7: 4.06681 | D7: 0.000747474 | E7: 97.292 | F7: 0.0178821 | G7: 1.90971 | H7: 0.00328648 | I7: 7957.62 | J7: 766.194 | K7: 14257.5 | L7: 129.112 | M7: 600.524 | N7: 1.0435 | O7: 1.92503 | P7: 0.00379419 | Q7: 605.341 | R7: 0.670664 | S7: 506.88 | T7: 0.0422829 | U7: 22.1396 | V7: 0.00486424 | W7: 26.4237 | X7: 0.0286177 | Y7: 3.72154 | Z7: 0.000490837 | AA7: 3.03478 | AB7: 0.000314097 | AC7: 20 | AD7: 0 | AE7: 17 | AF7: 0 | AG7: 3 | AH7: -1 | AI7: Disabled
A8: 44838.536 | B8: 10/04/2022 12:52:14.852 | C8: 4.06976 | D8: 0.00154173 | E8: 97.3628 | F8: 0.0368835 | G8: 1.91178 | H8: 0.00303554 | I8: 8296.51 | J8: 557.251 | K8: 14190.8 | L8: 103.551 | M8: 601.244 | N8: 1.31159 | O8: 1.92777 | P8: 0.00245013 | Q8: 606.274 | R8: 1.43811 | S8: 506.856 | T8: 0.038611 | U8: 22.1346 | V8: 0.00370176 | W8: 26.436 | X8: 0.0290433 | Y8: 3.72158 | Z8: 0.000382011 | AA8: 3.03424 | AB8: 0.000346964 | AC8: 20 | AD8: 0 | AE8: 17 | AF8: 0 | AG8: 3 | AH8: -1 | AI8: Disabled
A9: 44838.536 | B9: 10/04/2022 12:52:19.825 | C9: 4.06965 | D9: 0.00243682 | E9: 97.3601 | F9: 0.0582972 | G9: 1.91144 | H9: 0.00247357 | I9: 10072.7 | J9: 116.244 | K9: 14312.8 | L9: 116.579 | M9: 605.344 | N9: 0.813709 | O9: 1.93089 | P9: 0.00243843 | Q9: 611.504 | R9: 0.846912 | S9: 506.84 | T9: 0.0465645 | U9: 22.119 | V9: 0.00349388 | W9: 26.4012 | X9: 0.0234146 | Y9: 3.7211 | Z9: 0.000297995 | AA9: 3.03442 | AB9: 0.00023891 | AC9: 20 | AD9: 0 | AE9: 17 | AF9: 0 | AG9: 3 | AH9: -1 | AI9: Disabled
A10: 44838.536 | B10: 10/04/2022 12:52:24.798 | C10: 4.06834 | D10: 0.00140047 | E10: 97.3287 | F10: 0.0335041 | G10: 1.91256 | H10: 0.00381665 | I10: 10719.9 | J10: 411.693 | K10: 14396.2 | L10: 326.249 | M10: 606.777 | N10: 1.4998 | O10: 1.93329 | P10: 0.00459141 | Q10: 613.352 | R10: 1.6638 | S10: 506.844 | T10: 0.0463762 | U10: 22.1253 | V10: 0.00609809 | W10: 26.4292 | X10: 0.0350543 | Y10: 3.72082 | Z10: 0.000671873 | AA10: 3.03427 | AB10: 0.000428262 | AC10: 20 | AD10: 0 | AE10: 17 | AF10: 0 | AG10: 3 | AH10: -1 | AI10: Disabled
A11: 44838.536 | B11: 10/04/2022 12:52:29.770 | C11: 4.06939 | D11: 0.0026853 | E11: 97.3539 | F11: 0.0642417 | G11: 1.91284 | H11: 0.00260038 | I11: 10976.2 | J11: 281.37 | K11: 14362.3 | L11: 188.051 | M11: 608.99 | N11: 0.585276 | O11: 1.93407 | P11: 0.0025293 | Q11: 615.748 | R11: 0.491351 | S11: 506.869 | T11: 0.031865 | U11: 22.12 | V11: 0.00307787 | W11: 26.4602 | X11: 0.0306445 | Y11: 3.72053 | Z11: 0.000306165 | AA11: 3.034 | AB11: 0.000471614 | AC11: 20 | AD11: 0 | AE11: 17 | AF11: 0 | AG11: 3 | AH11: -1 | AI11: Disabled
A12: 44838.537 | B12: 10/04/2022 12:52:34.744 | C12: 4.06791 | D12: 0.000763249 | E12: 97.3184 | F12: 0.0182595 | G12: 1.91499 | H12: 0.00115299 | I12: 11392.3 | J12: 123.772 | K12: 14535.8 | L12: 116.881 | M12: 610.964 | N12: 1.42708 | O12: 1.93705 | P12: 0.00110825 | Q12: 618.004 | R12: 1.45848 | S12: 506.858 | T12: 0.0390066 | U12: 22.1207 | V12: 0.00721781 | W12: 26.4772 | X12: 0.0303313 | Y12: 3.72036 | Z12: 0.000882135 | AA12: 3.03421 | AB12: 0.000459178 | AC12: 20 | AD12: 0 | AE12: 17 | AF12: 0 | AG12: 3 | AH12: -1 | AI12: Disabled
A13: 44838.537 | B13: 10/04/2022 12:52:39.715 | C13: 4.0711 | D13: 0.000650697 | E13: 97.3948 | F13: 0.0155669 | G13: 1.91653 | H13: 0.00284304 | I13: 11593.6 | J13: 166.906 | K13: 14545.2 | L13: 68.8528 | M13: 613.659 | N13: 1.22863 | O13: 1.93901 | P13: 0.00289721 | Q13: 620.857 | R13: 1.18936 | S13: 506.894 | T13: 0.0247163 | U13: 22.1305 | V13: 0.00779379 | W13: 26.4846 | X13: 0.0105131 | Y13: 3.71977 | Z13: 0.000506762 | AA13: 3.03397 | AB13: 0.000178055 | AC13: 20 | AD13: 0 | AE13: 17 | AF13: 0 | AG13: 3 | AH13: -1 | AI13: Disabled
A14: 44838.537 | B14: 10/04/2022 12:52:44.689 | C14: 4.06908 | D14: 0.00134372 | E14: 97.3464 | F14: 0.0321464 | G14: 1.91508 | H14: 0.00107491 | I14: 11535.6 | J14: 222.329 | K14: 14513.2 | L14: 122.007 | M14: 615.645 | N14: 1.61757 | O14: 1.93743 | P14: 0.00137503 | Q14: 622.83 | R14: 1.72156 | S14: 506.878 | T14: 0.0728842 | U14: 22.1223 | V14: 0.00176036 | W14: 26.5104 | X14: 0.0190571 | Y14: 3.71955 | Z14: 0.000558168 | AA14: 3.03401 | AB14: 0.000527107 | AC14: 20 | AD14: 0 | AE14: 17 | AF14: 0 | AG14: 3 | AH14: -1 | AI14: Disabled
... A318: 44838.554 | B318: 10/04/2022 13:17:56.522 | C318: 4.11247 | D318: 0.000271126 | E318: 98.3845 | F318: 0.00648626 | G318: 1.92462 | H318: 0.00168398 | I318: 11942.5 | J318: 856.748 | K318: 14970.5 | L318: 114.041 | M318: 534.081 | N318: 0.922968 | O318: 1.94789 | P318: 0.00241241 | Q318: 540.538 | R318: 1.36464 | S318: 506.79 | T318: 0.0332674 | U318: 22.5579 | V318: 0.000997517 | W318: 27.476 | X318: 0.0219824 | Y318: 3.71788 | Z318: 0.000778985 | AA318: 3.03217 | AB318: 0.000242729 | AC318: 20 | AD318: 0 | AE318: 17 | AF318: 0 | AG318: 3 | AH318: -1 | AI318: Disabled

Sheet f0004
A1: SN:3K60180500001585 BD:Jul 23 2018 VC:834b9c1 MD5:48f99e4865ed8b810be1bb0eaaabf929
A2: SysTime | B2: Time | C2: Batt_v | D2: Batt_v_sd | E2: BATT_PERCENT | F2: BATT_PERCENT_sd | G2: [CH4]_ppm | H2: [CH4]_ppm_sd | I2: [H2O]_ppm | J2: [H2O]_ppm_sd | K2: [H2Oa]_ppm | L2: [H2Oa]_ppm_sd | M2: [CO2]_ppm | N2: [CO2]_ppm_sd | O2: [CH4]d_ppm | P2: [CH4]d_ppm_sd | Q2: [CO2]d_ppm | R2: [CO2]d_ppm_sd | S2: GasP_torr | T2: GasP_torr_sd | U2: GasT_C | V2: GasT_C_sd | W2: AmbT_C | X2: AmbT_C_sd | Y2: RD0_us | Z2: RD0_us_sd | AA2: RD1_us | AB2: RD1_us_sd | AC2: Temp_Status_mA | AD2: Temp_Status_mA_sd | AE2: Analyzer_Status_mA | AF2: Analyzer_Status_mA_sd | AG2: Fit_Flag | AH2: MIU_VALVE | AI2: MIU_DESC
A3: 44838.557 | B3: 10/04/2022 13:21:48.389 | C3: 4.11573 | D3: 0.000328131 | E3: 98.4625 | F3: 0.00785001 | G3: 1.91699 | H3: 0.00230079 | I3: 5098.34 | J3: 577.409 | K3: 14520.4 | L3: 145.128 | M3: 656.217 | N3: 2.5388 | O3: 1.92681 | P3: 0.003307 | Q3: 659.581 | R3: 2.91032 | S3: 506.738 | T3: 0.0468058 | U3: 22.5962 | V3: 0.00247235 | W3: 27.2285 | X3: 0.0303842 | Y3: 3.72222 | Z3: 0.000250173 | AA3: 3.03454 | AB3: 0.000478684 | AC3: 20 | AD3: 0 | AE3: 17 | AF3: 0 | AG3: 2 | AH3: -1 | AI3: Disabled
A4: 44838.557 | B4: 10/04/2022 13:21:53.361 | C4: 4.11583 | D4: 0.000122651 | E4: 98.4649 | F4: 0.00293423 | G4: 1.91907 | H4: 0.00259749 | I4: 6868.16 | J4: 666.294 | K4: 14649 | L4: 136.157 | M4: 661.391 | N4: 2.59301 | O4: 1.93235 | P4: 0.00324208 | Q4: 665.967 | R4: 3.02206 | S4: 506.759 | T4: 0.0284053 | U4: 22.5976 | V4: 0.000960794 | W4: 27.2219 | X4: 0.0347351 | Y4: 3.72131 | Z4: 0.000220162 | AA4: 3.03397 | AB4: 0.000339365 | AC4: 20 | AD4: 0 | AE4: 17 | AF4: 0 | AG4: 2 | AH4: -1 | AI4: Disabled
A5: 44838.557 | B5: 10/04/2022 13:21:58.333 | C5: 4.11642 | D5: 0.000216596 | E5: 98.479 | F5: 0.00518172 | G5: 1.92072 | H5: 0.00320114 | I5: 8630.06 | J5: 305.52 | K5: 14861.7 | L5: 110.13 | M5: 665.409 | N5: 0.120675 | O5: 1.93744 | P5: 0.00374971 | Q5: 671.202 | R5: 0.306564 | S5: 506.727 | T5: 0.045838 | U5: 22.5999 | V5: 0.000574263 | W5: 27.1714 | X5: 0.0104834 | Y5: 3.72073 | Z5: 0.00101248 | AA5: 3.0341 | AB5: 0.000224262 | AC5: 20 | AD5: 0 | AE5: 17 | AF5: 0 | AG5: 3 | AH5: -1 | AI5: Disabled
A6: 44838.557 | B6: 10/04/2022 13:22:03.306 | C6: 4.11652 | D6: 0.000182466 | E6: 98.4812 | F6: 0.00436521 | G6: 1.92085 | H6: 0.00244201 | I6: 8274.11 | J6: 693.7 | K6: 14807.3 | L6: 101.13 | M6: 667.254 | N6: 1.00577 | O6: 1.93688 | P6: 0.00366876 | Q6: 672.822 | R6: 1.43091 | S6: 506.746 | T6: 0.0571595 | U6: 22.6009 | V6: 0.000696242 | W6: 27.1497 | X6: 0.0141325 | Y6: 3.72061 | Z6: 0.000654709 | AA6: 3.03358 | AB6: 0.000302823 | AC6: 20 | AD6: 0 | AE6: 17 | AF6: 0 | AG6: 3 | AH6: -1 | AI6: Disabled
A7: 44838.557 | B7: 10/04/2022 13:22:08.278 | C7: 4.11677 | D7: 0.000178654 | E7: 98.4872 | F7: 0.00427401 | G7: 1.92281 | H7: 0.00393765 | I7: 10225 | J7: 228.98 | K7: 14854.2 | L7: 128.278 | M7: 670.867 | N7: 1.68697 | O7: 1.94268 | P7: 0.00423323 | Q7: 677.797 | R7: 1.75006 | S7: 506.793 | T7: 0.026304 | U7: 22.6005 | V7: 0.000957705 | W7: 27.1132 | X7: 0.0344961 | Y7: 3.72074 | Z7: 0.000616978 | AA7: 3.03358 | AB7: 0.000333671 | AC7: 20 | AD7: 0 | AE7: 17 | AF7: 0 | AG7: 3 | AH7: -1 | AI7: Disabled
A8: 44838.557 | B8: 10/04/2022 13:22:13.251 | C8: 4.11703 | D8: 0.00014576 | E8: 98.4937 | F8: 0.00348707 | G8: 1.92238 | H8: 0.00285063 | I8: 10746.9 | J8: 276.119 | K8: 14898.4 | L8: 142.436 | M8: 673.009 | N8: 0.532483 | O8: 1.94326 | P8: 0.00328858 | Q8: 680.321 | R8: 0.696821 | S8: 506.782 | T8: 0.0475633 | U8: 22.6008 | V8: 0.00100091 | W8: 27.0994 | X8: 0.0252413 | Y8: 3.71991 | Z8: 0.00080346 | AA8: 3.0336 | AB8: 0.000266655 | AC8: 20 | AD8: 0 | AE8: 17 | AF8: 0 | AG8: 3 | AH8: -1 | AI8: Disabled
A9: 44838.557 | B9: 10/04/2022 13:22:18.225 | C9: 4.11683 | D9: 0.000201698 | E9: 98.4888 | F9: 0.0048253 | G9: 1.92458 | H9: 0.00368478 | I9: 11240.7 | J9: 181.654 | K9: 14912.3 | L9: 88.2667 | M9: 675.544 | N9: 0.836025 | O9: 1.94646 | P9: 0.00378077 | Q9: 683.224 | R9: 0.944153 | S9: 506.768 | T9: 0.0579216 | U9: 22.5995 | V9: 0.00102851 | W9: 27.0829 | X9: 0.0168162 | Y9: 3.71951 | Z9: 0.000662346 | AA9: 3.03345 | AB9: 0.000204764 | AC9: 20 | AD9: 0 | AE9: 17 | AF9: 0 | AG9: 3 | AH9: -1 | AI9: Disabled
A10: 44838.557 | B10: 10/04/2022 13:22:23.197 | C10: 4.11656 | D10: 0.000204735 | E10: 98.4822 | F10: 0.00489797 | G10: 1.92378 | H10: 0.000849033 | I10: 11500.9 | J10: 87.3221 | K10: 14917.8 | L10: 122.316 | M10: 677.266 | N10: 0.828636 | O10: 1.94616 | P10: 0.000792724 | Q10: 685.146 | R10: 0.834848 | S10: 506.757 | T10: 0.0702528 | U10: 22.599 | V10: 0.00264182 | W10: 27.1109 | X10: 0.0445201 | Y10: 3.71984 | Z10: 0.000380199 | AA10: 3.03334 | AB10: 0.00026008 | AC10: 20 | AD10: 0 | AE10: 17 | AF10: 0 | AG10: 3 | AH10: -1 | AI10: Disabled
A11: 44838.557 | B11: 10/04/2022 13:22:28.169 | C11: 4.11636 | D11: 0.000132089 | E11: 98.4775 | F11: 0.00316003 | G11: 1.92702 | H11: 0.00138271 | I11: 11737.9 | J11: 234.554 | K11: 15087.3 | L11: 126.689 | M11: 680.117 | N11: 1.57515 | O11: 1.94991 | P11: 0.00163493 | Q11: 688.195 | R11: 1.65549 | S11: 506.755 | T11: 0.0665486 | U11: 22.6017 | V11: 0.00313551 | W11: 27.1287 | X11: 0.0155787 | Y11: 3.71954 | Z11: 0.000330961 | AA11: 3.03311 | AB11: 0.000379696 | AC11: 20 | AD11: 0 | AE11: 17 | AF11: 0 | AG11: 3 | AH11: -1 | AI11: Disabled
A12: 44838.557 | B12: 10/04/2022 13:22:33.142 | C12: 4.11656 | D12: 0.00014875 | E12: 98.4822 | F12: 0.00355861 | G12: 1.92662 | H12: 0.00393082 | I12: 11758.3 | J12: 160.958 | K12: 14964.6 | L12: 151.801 | M12: 682.782 | N12: 1.46589 | O12: 1.94955 | P12: 0.00413422 | Q12: 690.905 | R12: 1.46715 | S12: 506.756 | T12: 0.0374519 | U12: 22.6024 | V12: 0.00095466 | W12: 27.1067 | X12: 0.0222152 | Y12: 3.71896 | Z12: 0.000475802 | AA12: 3.03297 | AB12: 0.00013146 | AC12: 20 | AD12: 0 | AE12: 17 | AF12: 0 | AG12: 3 | AH12: -1 | AI12: Disabled
A13: 44838.557 | B13: 10/04/2022 13:22:38.115 | C13: 4.11688 | D13: 0.00028658 | E13: 98.4899 | F13: 0.00685597 | G13: 1.92708 | H13: 0.000988597 | I13: 11992.2 | J13: 200.438 | K13: 15106 | L13: 131.692 | M13: 685.942 | N13: 1.44335 | O13: 1.95047 | P13: 0.00113839 | Q13: 694.268 | R13: 1.5658 | S13: 506.754 | T13: 0.0757101 | U13: 22.6028 | V13: 0.000639325 | W13: 27.1349 | X13: 0.0295549 | Y13: 3.7193 | Z13: 0.000560434 | AA13: 3.03287 | AB13: 0.000244253 | AC13: 20 | AD13: 0 | AE13: 17 | AF13: 0 | AG13: 3 | AH13: -1 | AI13: Disabled
A14: 44838.557 | B14: 10/04/2022 13:22:43.095 | C14: 4.11661 | D14: 0.000290056 | E14: 98.4834 | F14: 0.00693914 | G14: 1.9262 | H14: 0.00171974 | I14: 11905.3 | J14: 121.088 | K14: 14950.7 | L14: 93.8945 | M14: 688.308 | N14: 1.7551 | O14: 1.9494 | P14: 0.00173305 | Q14: 696.601 | R14: 1.78504 | S14: 506.778 | T14: 0.0312264 | U14: 22.6005 | V14: 0.000819904 | W14: 27.1439 | X14: 0.030112 | Y14: 3.71904 | Z14: 0.000630343 | AA14: 3.03285 | AB14: 0.000473396 | AC14: 20 | AD14: 0 | AE14: 17 | AF14: 0 | AG14: 3 | AH14: -1 | AI14: Disabled
... A53: 44838.56 | B53: 10/04/2022 13:25:57.030 | C53: 4.11833 | D53: 0.000174616 | E53: 98.5246 | F53: 0.00417742 | G53: 1.92688 | H53: 0.00205538 | I53: 11540.5 | J53: 983.004 | K53: 15008.4 | L53: 29.3883 | M53: 783.509 | N53: 1.39955 | O53: 1.94938 | P53: 0.0012073 | Q53: 792.657 | R53: 1.64394 | S53: 506.775 | T53: 0.057735 | U53: 22.6277 | V53: 0.00199124 | W53: 27.0915 | X53: 0.0350566 | Y53: 3.71762 | Z53: 0.000551836 | AA53: 3.03168 | AB53: 0.000394351 | AC53: 20 | AD53: 0 | AE53: 17 | AF53: 0 | AG53: 3 | AH53: -1 | AI53: Disabled

Sheet compiled
A1: SysTime | B1: Time | C1: Batt_v | D1: Batt_v_sd | E1: BATT_PERCENT | F1: BATT_PERCENT_sd | G1: [CH4]_ppm | H1: [CH4]_ppm_sd | I1: [H2O]_ppm | J1: [H2O]_ppm_sd | K1: [H2Oa]_ppm | L1: [H2Oa]_ppm_sd | M1: [CO2]_ppm | N1: [CO2]_ppm_sd | O1: [CH4]d_ppm | P1: [CH4]d_ppm_sd | Q1: [CO2]d_ppm | R1: [CO2]d_ppm_sd | S1: GasP_torr | T1: GasP_torr_sd | U1: GasT_C | V1: GasT_C_sd | W1: AmbT_C | X1: AmbT_C_sd | Y1: RD0_us | Z1: RD0_us_sd | AA1: RD1_us | AB1: RD1_us_sd | AC1: Temp_Status_mA | AD1: Temp_Status_mA_sd | AE1: Analyzer_Status_mA | AF1: Analyzer_Status_mA_sd | AG1: Fit_Flag | AH1: MIU_VALVE | AI1: MIU_DESC
A2: 44838.429 | B2: 10/04/2022 10:18:11.622 | C2: 3.63513 | D2: 0 | E2: 43.4824 | F2: 0 | G2: 1.92229 | H2: 0 | I2: 2228.77 | J2: 0 | K2: 10547.4 | L2: 0 | M2: 853.118 | N2: 0 | O2: 0.963294 | P2: 0 | Q2: 427.512 | R2: 0 | S2: 507.76 | T2: 0 | U2: 14.168 | V2: 0 | W2: 17.0334 | X2: 0 | Y2: 3.72377 | Z2: 0 | AA2: 3.03796 | AB2: 0 | AC2: 20 | AD2: 0 | AE2: 17 | AF2: 0 | AG2: 2 | AH2: -1 | AI2: Disabled
A3: 44838.429 | B3: 10/04/2022 10:18:16.595 | C3: 3.63941 | D3: 0.00106904 | E3: 87.0673 | F3: 0.0255751 | G3: 1.92058 | H3: 0.00266303 | I3: 2783.01 | J3: 840.282 | K3: 10746.3 | L3: 228.149 | M3: 857.07 | N3: 1.94216 | O3: 1.92593 | P3: 0.00211667 | Q3: 859.463 | R3: 2.60082 | S3: 507.743 | T3: 0.0307744 | U3: 14.1648 | V3: 0.00286805 | W3: 17.0356 | X3: 0.0160398 | Y3: 3.72452 | Z3: 0.00112189 | AA3: 3.03786 | AB3: 0.000416981 | AC3: 20 | AD3: 0 | AE3: 17 | AF3: 0 | AG3: 2 | AH3: -1 | AI3: Disabled
A4: 44838.429 | B4: 10/04/2022 10:18:21.568 | C4: 3.63857 | D4: 0.00146066 | E4: 87.0472 | F4: 0.0349439 | G4: 1.92438 | H4: 0.00363289 | I4: 4235.19 | J4: 394.818 | K4: 10630.9 | L4: 303.018 | M4: 864.461 | N4: 1.4234 | O4: 1.93257 | P4: 0.00421924 | Q4: 868.138 | R4: 1.70147 | S4: 507.753 | T4: 0.0299492 | U4: 14.1589 | V4: 0.000770588 | W4: 17.0572 | X4: 0.010957 | Y4: 3.72385 | Z4: 0.000199009 | AA4: 3.0371 | AB4: 0.000371263 | AC4: 20 | AD4: 0 | AE4: 17 | AF4: 0 | AG4: 2 | AH4: -1 | AI4: Disabled
A5: 44838.429 | B5: 10/04/2022 10:18:26.541 | C5: 3.63676 | D5: 0.00132289 | E5: 87.0038 | F5: 0.031648 | G5: 1.92415 | H5: 0.00127904 | I5: 6036.46 | J5: 552.958 | K5: 10676.3 | L5: 214.891 | M5: 866.922 | N5: 1.48574 | O5: 1.93584 | P5: 0.00209683 | Q5: 872.188 | R5: 1.96634 | S5: 507.761 | T5: 0.0144471 | U5: 14.1607 | V5: 0.0033516 | W5: 17.0785 | X5: 0.0365115 | Y5: 3.72341 | Z5: 0.000548593 | AA5: 3.03748 | AB5: 0.000385639 | AC5: 20 | AD5: 0 | AE5: 17 | AF5: 0 | AG5: 3 | AH5: -1 | AI5: Disabled
A6: 44838.43 | B6: 10/04/2022 10:18:31.521 | C6: 3.63597 | D6: 0.00130819 | E6: 86.985 | F6: 0.0312964 | G6: 1.92501 | H6: 0.00204844 | I6: 6358.62 | J6: 406.111 | K6: 10681.8 | L6: 239.541 | M6: 869.778 | N6: 1.04667 | O6: 1.93733 | P6: 0.00193323 | Q6: 875.344 | R6: 1.17485 | S6: 507.724 | T6: 0.0548227 | U6: 14.1609 | V6: 0.0050294 | W6: 17.091 | X6: 0.023571 | Y6: 3.72337 | Z6: 0.000316757 | AA6: 3.03693 | AB6: 0.000504146 | AC6: 20 | AD6: 0 | AE6: 17 | AF6: 0 | AG6: 3 | AH6: -1 | AI6: Disabled
A7: 44838.43 | B7: 10/04/2022 10:18:36.493 | C7: 3.63382 | D7: 0.00113742 | E7: 86.9336 | F7: 0.027211 | G7: 1.92714 | H7: 0.00406584 | I7: 7308.31 | J7: 560.576 | K7: 10766.1 | L7: 463.851 | M7: 871.364 | N7: 1.28276 | O7: 1.94133 | P7: 0.00431501 | Q7: 877.779 | R7: 1.2954 | S7: 507.752 | T7: 0.0437165 | U7: 14.1672 | V7: 0.010284 | W7: 17.1268 | X7: 0.0191142 | Y7: 3.72316 | Z7: 0.000497983 | AA7: 3.0371 | AB7: 0.000264914 | AC7: 20 | AD7: 0 | AE7: 17 | AF7: 0 | AG7: 3 | AH7: -1 | AI7: Disabled
A8: 44838.43 | B8: 10/04/2022 10:18:41.465 | C8: 3.63359 | D8: 0.000495247 | E8: 86.9279 | F8: 0.011848 | G8: 1.93063 | H8: 0.00237245 | I8: 7606.09 | J8: 662.809 | K8: 10860.2 | L8: 425.22 | M8: 874.826 | N8: 1.13524 | O8: 1.94542 | P8: 0.00291319 | Q8: 881.532 | R8: 1.54726 | S8: 507.733 | T8: 0.0548648 | U8: 14.1605 | V8: 0.00882173 | W8: 17.1575 | X8: 0.0272332 | Y8: 3.72195 | Z8: 0.000682863 | AA8: 3.03681 | AB8: 0.000463218 | AC8: 20 | AD8: 0 | AE8: 17 | AF8: 0 | AG8: 3 | AH8: -1 | AI8: Disabled
A9: 44838.43 | B9: 10/04/2022 10:18:46.439 | C9: 3.63289 | D9: 0.00144015 | E9: 86.9112 | F9: 0.0344534 | G9: 1.93041 | H9: 0.00320161 | I9: 7791.87 | J9: 328.108 | K9: 10690.2 | L9: 119.668 | M9: 876.026 | N9: 1.09157 | O9: 1.94557 | P9: 0.00366442 | Q9: 882.905 | R9: 1.20193 | S9: 507.713 | T9: 0.0453368 | U9: 14.1541 | V9: 0.0087883 | W9: 17.1833 | X9: 0.0237966 | Y9: 3.72219 | Z9: 0.000472232 | AA9: 3.03685 | AB9: 0.000822044 | AC9: 20 | AD9: 0 | AE9: 17 | AF9: 0 | AG9: 3 | AH9: -1 | AI9: Disabled
A10: 44838.43 | B10: 10/04/2022 10:18:51.411 | C10: 3.63246 | D10: 0.00121149 | E10: 86.9011 | F10: 0.0289831 | G10: 1.93211 | H10: 0.00347416 | I10: 8235.83 | J10: 320.516 | K10: 10842.5 | L10: 300.381 | M10: 877.786 | N10: 1.0734 | O10: 1.94815 | P10: 0.00319571 | Q10: 885.076 | R10: 1.14028 | S10: 507.697 | T10: 0.049449 | U10: 14.1462 | V10: 0.00232943 | W10: 17.1899 | X10: 0.0296315 | Y10: 3.72199 | Z10: 0.00041535 | AA10: 3.03713 | AB10: 0.000466585 | AC10: 20 | AD10: 0 | AE10: 17 | AF10: 0 | AG10: 3 | AH10: -1 | AI10: Disabled
A11: 44838.43 | B11: 10/04/2022 10:18:56.383 | C11: 3.63086 | D11: 0.00167617 | E11: 86.8626 | F11: 0.0400997 | G11: 1.93231 | H11: 0.00234679 | I11: 8255.07 | J11: 343.526 | K11: 10773.2 | L11: 427.128 | M11: 878.917 | N11: 0.90498 | O11: 1.94839 | P11: 0.00268241 | Q11: 886.233 | R11: 0.837941 | S11: 507.697 | T11: 0.0450291 | U11: 14.148 | V11: 0.00382317 | W11: 17.2085 | X11: 0.0227274 | Y11: 3.7218 | Z11: 0.000549135 | AA11: 3.03647 | AB11: 0.000524441 | AC11: 20 | AD11: 0 | AE11: 17 | AF11: 0 | AG11: 3 | AH11: -1 | AI11: Disabled
A12: 44838.43 | B12: 10/04/2022 10:19:01.357 | C12: 3.63049 | D12: 0.00118681 | E12: 86.8539 | F12: 0.0283925 | G12: 1.93253 | H12: 0.00508014 | I12: 8866.29 | J12: 359.701 | K12: 11036.5 | L12: 462.107 | M12: 878.826 | N12: 2.04374 | O12: 1.94982 | P12: 0.00572616 | Q12: 886.688 | R12: 2.13249 | S12: 507.678 | T12: 0.056018 | U12: 14.1473 | V12: 0.00422216 | W12: 17.2346 | X12: 0.0224957 | Y12: 3.72097 | Z12: 0.000747112 | AA12: 3.03584 | AB12: 0.000432972 | AC12: 20 | AD12: 0 | AE12: 17 | AF12: 0 | AG12: 3 | AH12: -1 | AI12: Disabled
A13: 44838.43 | B13: 10/04/2022 10:19:06.328 | C13: 3.62779 | D13: 0.00514383 | E13: 86.7892 | F13: 0.123058 | G13: 1.93215 | H13: 0.00555321 | I13: 8992.94 | J13: 335.598 | K13: 11061.5 | L13: 266.161 | M13: 881.066 | N13: 2.35577 | O13: 1.94968 | P13: 0.0054212 | Q13: 889.061 | R13: 2.29677 | S13: 507.642 | T13: 0.06755 | U13: 14.1426 | V13: 0.00189531 | W13: 17.2468 | X13: 0.0287507 | Y13: 3.72145 | Z13: 0.000603824 | AA13: 3.03621 | AB13: 0.000406385 | AC13: 20 | AD13: 0 | AE13: 10.6 | AF13: 3.57771 | AG13: 3 | AH13: -1 | AI13: Disabled
... A1674: 44838.56 | B1674: 10/04/2022 13:25:57.030 | C1674: 4.11833 | D1674: 0.000174616 | E1674: 98.5246 | F1674: 0.00417742 | G1674: 1.92688 | H1674: 0.00205538 | I1674: 11540.5 | J1674: 983.004 | K1674: 15008.4 | L1674: 29.3883 | M1674: 783.509 | N1674: 1.39955 | O1674: 1.94938 | P1674: 0.0012073 | Q1674: 792.657 | R1674: 1.64394 | S1674: 506.775 | T1674: 0.057735 | U1674: 22.6277 | V1674: 0.00199124 | W1674: 27.0915 | X1674: 0.0350566 | Y1674: 3.71762 | Z1674: 0.000551836 | AA1674: 3.03168 | AB1674: 0.000394351 | AC1674: 20 | AD1674: 0 | AE1674: 17 | AF1674: 0 | AG1674: 3 | AH1674: -1 | AI1674: Disabled

Sheet 1000cm
A1: Seconds | B1: SysTime | C1: Time | D1: Batt_v | E1: Batt_v_sd | F1: BATT_PERCENT | G1: BATT_PERCENT_sd | H1: [CH4]_ppm | I1: [CH4]_ppm_sd | J1: [H2O]_ppm | K1: [H2O]_ppm_sd | L1: [H2Oa]_ppm | M1: [H2Oa]_ppm_sd | N1: [CO2]_ppm | O1: [CO2]_ppm_sd | P1: [CH4]d_ppm | Q1: [CH4]d_ppm_sd | R1: [CO2]d_ppm | S1: [CO2]d_ppm_sd | T1: GasP_torr | U1: GasP_torr_sd | V1: GasT_C | W1: GasT_C_sd | X1: AmbT_C | Y1: AmbT_C_sd | Z1: RD0_us | AA1: RD0_us_sd | AB1: RD1_us | AC1: RD1_us_sd | AD1: Temp_Status_mA | AE1: Temp_Status_mA_sd | AF1: Analyzer_Status_mA | AG1: Analyzer_Status_mA_sd | AH1: Fit_Flag | AI1: MIU_VALVE | AJ1: MIU_DESC
A2: 0 | B2: 44838.435 | C2: 10/04/2022 10:26:04.096 | D2: 3.56831 | E2: 0.00204445 | F2: 85.3663 | G2: 0.0489102 | H2: 1.92242 | I2: 0.00550113 | J2: 9373.4 | K2: 574.662 | L2: 11010.5 | M2: 497.022 | N2: 567.528 | O2: 2.61447 | P2: 1.94061 | Q2: 0.00635295 | R2: 572.899 | S2: 2.89813 | T2: 507.465 | U2: 0.10918 | V2: 14.7012 | W2: 0.00465171 | X2: 20.2287 | Y2: 0.0482817 | Z2: 3.71691 | AA2: 0.00161354 | AB2: 3.03182 | AC2: 0.000375042 | AD2: 20 | AE2: 0 | AF2: 9 | AG2: 0 | AH2: 3 | AI2: -1 | AJ2: Disabled
A3: 5 | B3: 44838.435 | C3: 10/04/2022 10:26:09.074 | D3: 3.56649 | E3: 0.00162701 | F3: 85.3227 | G3: 0.0389237 | H3: 1.92714 | I3: 0.00591016 | J3: 9206.97 | K3: 565.202 | L3: 11069.9 | M3: 368.034 | N3: 568.797 | O3: 2.47533 | P3: 1.94504 | Q3: 0.00567285 | R3: 574.083 | S3: 2.62315 | T3: 507.48 | U3: 0.120176 | V3: 14.7131 | W3: 0.00505282 | X3: 20.2643 | Y3: 0.0552282 | Z3: 3.71705 | AA3: 0.000936741 | AB3: 3.03219 | AC3: 0.000671893 | AD3: 20 | AE3: 0 | AF3: 9 | AG3: 0 | AH3: 3 | AI3: -1 | AJ3: Disabled
A4: 10 | B4: 44838.435 | C4: 10/04/2022 10:26:14.047 | D4: 3.56561 | E4: 0.00189064 | F4: 85.3017 | G4: 0.0452306 | H4: 1.92642 | I4: 0.00459206 | J4: 8998.25 | K4: 648.252 | L4: 10861.9 | M4: 556.154 | N4: 571.338 | O4: 1.47418 | P4: 1.94391 | Q4: 0.00502192 | R4: 576.526 | S4: 1.50114 | T4: 507.482 | U4: 0.0880366 | V4: 14.7269 | W4: 0.00597387 | X4: 20.2986 | Y4: 0.062964 | Z4: 3.71788 | AA4: 0.00102159 | AB4: 3.03227 | AC4: 0.000565399 | AD4: 20 | AE4: 0 | AF4: 9 | AG4: 0 | AH4: 3 | AI4: -1 | AJ4: Disabled
A5: 15 | B5: 44838.435 | C5: 10/04/2022 10:26:19.020 | D5: 3.56596 | E5: 0.00244839 | F5: 85.31 | G5: 0.0585738 | H5: 1.9297 | I5: 0.00594639 | J5: 9414.45 | K5: 366.168 | L5: 11210.2 | M5: 225.643 | N5: 572.246 | O5: 2.02462 | P5: 1.94804 | Q5: 0.00662594 | R5: 577.684 | S5: 1.99872 | T5: 507.467 | U5: 0.103566 | V5: 14.74 | W5: 0.00692077 | X5: 20.3113 | Y5: 0.0672768 | Z5: 3.71725 | AA5: 0.00135303 | AB5: 3.03177 | AC5: 0.000670275 | AD5: 20 | AE5: 0 | AF5: 9 | AG5: 0 | AH5: 3 | AI5: -1 | AJ5: Disabled
A6: 20 | B6: 44838.435 | C6: 10/04/2022 10:26:23.993 | D6: 3.56611 | E6: 0.00198831 | F6: 85.3136 | G6: 0.0475672 | H6: 1.92352 | I6: 0.00570674 | J6: 9022.38 | K6: 560.621 | L6: 11075.9 | M6: 473.099 | N6: 577.289 | O6: 2.24976 | P6: 1.94103 | Q6: 0.00627623 | R6: 582.546 | S6: 2.51795 | T6: 507.46 | U6: 0.11928 | V6: 14.7505 | W6: 0.00534559 | X6: 20.3385 | Y6: 0.0656504 | Z6: 3.71701 | AA6: 0.000772683 | AB6: 3.03235 | AC6: 0.000726786 | AD6: 20 | AE6: 0 | AF6: 9 | AG6: 0 | AH6: 3 | AI6: -1 | AJ6: Disabled
A7: 25 | B7: 44838.435 | C7: 10/04/2022 10:26:28.971 | D7: 3.56435 | E7: 0.00277128 | F7: 85.2716 | G7: 0.0662986 | H7: 1.92632 | I7: 0.00550042 | J7: 9249.83 | K7: 239.643 | L7: 11145.8 | M7: 174.955 | N7: 579.1 | O7: 1.72328 | P7: 1.94431 | Q7: 0.00595817 | R7: 584.507 | S7: 1.82041 | T7: 507.418 | U7: 0.0870674 | V7: 14.7594 | W7: 0.00237823 | X7: 20.3584 | Y7: 0.0578027 | Z7: 3.71711 | AA7: 0.000953634 | AB7: 3.03211 | AC7: 0.000469377 | AD7: 20 | AE7: 0 | AF7: 9 | AG7: 0 | AH7: 3 | AI7: -1 | AJ7: Disabled
A8: 30 | B8: 44838.435 | C8: 10/04/2022 10:26:33.945 | D8: 3.56205 | E8: 0.00177882 | F8: 85.2165 | G8: 0.0425556 | H8: 1.92812 | I8: 0.00409587 | J8: 9377.44 | K8: 439.082 | L8: 11401.8 | M8: 386.523 | N8: 582.611 | O8: 1.96792 | P8: 1.94637 | Q8: 0.00417168 | R8: 588.126 | S8: 1.81777 | T8: 507.445 | U8: 0.100868 | V8: 14.7714 | W8: 0.00351604 | X8: 20.3951 | Y8: 0.0650164 | Z8: 3.7174 | AA8: 0.00030848 | AB8: 3.03137 | AC8: 0.000622717 | AD8: 20 | AE8: 0 | AF8: 9 | AG8: 0 | AH8: 3 | AI8: -1 | AJ8: Disabled
A9: 35 | B9: 44838.435 | C9: 10/04/2022 10:26:38.917 | D9: 3.56242 | E9: 0.00244596 | F9: 85.2254 | G9: 0.0585157 | H9: 1.92557 | I9: 0.00434889 | J9: 9441.56 | K9: 335.924 | L9: 11191.2 | M9: 324.895 | N9: 584.559 | O9: 1.56648 | P9: 1.94393 | Q9: 0.00433754 | R9: 590.131 | S9: 1.5978 | T9: 507.458 | U9: 0.105085 | V9: 14.7804 | W9: 0.00387758 | X9: 20.4502 | Y9: 0.06762 | Z9: 3.71724 | AA9: 0.000503311 | AB9: 3.03177 | AC9: 0.000668837 | AD9: 20 | AE9: 0 | AF9: 9 | AG9: 0 | AH9: 3 | AI9: -1 | AJ9: Disabled
A10: 40 | B10: 44838.435 | C10: 10/04/2022 10:26:43.890 | D10: 3.56499 | E10: 0.00291704 | F10: 85.2868 | G10: 0.0697857 | H10: 1.92876 | I10: 0.00453003 | J10: 9256.13 | K10: 468.69 | L10: 11092.5 | M10: 517.807 | N10: 585.29 | O10: 1.25392 | P10: 1.94678 | Q10: 0.00455903 | R10: 590.758 | S10: 1.38288 | T10: 507.479 | U10: 0.10929 | V10: 14.7932 | W10: 0.00431211 | X10: 20.4778 | Y10: 0.0790695 | Z10: 3.71665 | AA10: 0.000682771 | AB10: 3.03199 | AC10: 0.00028056 | AD10: 20 | AE10: 0 | AF10: 9 | AG10: 0 | AH10: 3 | AI10: -1 | AJ10: Disabled
A11: 45 | B11: 44838.435 | C11: 10/04/2022 10:26:48.863 | D11: 3.56669 | E11: 0.00154366 | F11: 85.3275 | G11: 0.0369298 | H11: 1.92597 | I11: 0.00790534 | J11: 9098.78 | K11: 405.453 | L11: 11012.9 | M11: 115.243 | N11: 590.48 | O11: 1.40262 | P11: 1.94365 | Q11: 0.00863793 | R11: 595.903 | S11: 1.49886 | T11: 507.454 | U11: 0.144601 | V11: 14.8047 | W11: 0.00784949 | X11: 20.4678 | Y11: 0.0570519 | Z11: 3.71682 | AA11: 0.000645932 | AB11: 3.03164 | AC11: 0.000348464 | AD11: 20 | AE11: 0 | AF11: 9 | AG11: 0 | AH11: 3 | AI11: -1 | AJ11: Disabled
A12: 50 | B12: 44838.435 | C12: 10/04/2022 10:26:53.835 | D12: 3.56547 | E12: 0.00135188 | F12: 85.2983 | G12: 0.0323416 | H12: 1.92553 | I12: 0.00236353 | J12: 9231.13 | K12: 460.246 | L12: 11225.9 | M12: 323.35 | N12: 592.907 | O12: 1.38552 | P12: 1.94348 | Q12: 0.00321885 | R12: 598.432 | S12: 1.658 | T12: 507.409 | U12: 0.0997935 | V12: 14.8204 | W12: 0.00712519 | X12: 20.5141 | Y12: 0.0688437 | Z12: 3.71702 | AA12: 0.000315464 | AB12: 3.03137 | AC12: 0.000681877 | AD12: 20 | AE12: 0 | AF12: 9 | AG12: 0 | AH12: 3 | AI12: -1 | AJ12: Disabled
A13: 55 | B13: 44838.435 | C13: 10/04/2022 10:26:58.808 | D13: 3.56461 | E13: 0.00180941 | F13: 85.2777 | G13: 0.0432873 | H13: 1.92745 | I13: 0.00592563 | J13: 9331.39 | K13: 230.954 | L13: 11209.4 | M13: 225.218 | N13: 594.151 | O13: 1.03982 | P13: 1.94561 | Q13: 0.00577647 | R13: 599.748 | S13: 0.924409 | T13: 507.433 | U13: 0.132646 | V13: 14.8399 | W13: 0.00748418 | X13: 20.5463 | Y13: 0.0675945 | Z13: 3.71724 | AA13: 0.000509176 | AB13: 3.03148 | AC13: 0.000363875 | AD13: 20 | AE13: 0 | AF13: 9 | AG13: 0 | AH13: 3 | AI13: -1 | AJ13: Disabled
... A146: 720 | B146: 44838.443 | C146: 10/04/2022 10:38:00.209 | D146: 3.48383 | E146: 0.00238496 | F146: 83.3452 | G146: 0.0570564 | H146: 1.93253 | I146: 0.000613908 | J146: 9187.08 | K146: 196.565 | L146: 11518.2 | M146: 249.149 | N146: 874.146 | O146: 1.29063 | P146: 1.95045 | Q146: 0.000917459 | R146: 882.252 | S146: 1.30392 | T146: 507.332 | U146: 0.0795921 | V146: 16.7716 | W146: 0.00676007 | X146: 23.2804 | Y146: 0.0969339 | Z146: 3.72218 | AA146: 0.00106512 | AB146: 3.03513 | AC146: 0.000536827 | AD146: 20 | AE146: 0 | AF146: 9 | AG146: 0 | AH146: 3 | AI146: -1 | AJ146: Disabled

Sheet 800cm
A1: Seconds | B1: SysTime | C1: Time | D1: Batt_v | E1: Batt_v_sd | F1: BATT_PERCENT | G1: BATT_PERCENT_sd | H1: [CH4]_ppm | I1: [CH4]_ppm_sd | J1: [H2O]_ppm | K1: [H2O]_ppm_sd | L1: [H2Oa]_ppm | M1: [H2Oa]_ppm_sd | N1: [CO2]_ppm | O1: [CO2]_ppm_sd | P1: [CH4]d_ppm | Q1: [CH4]d_ppm_sd | R1: [CO2]d_ppm | S1: [CO2]d_ppm_sd | T1: GasP_torr | U1: GasP_torr_sd | V1: GasT_C | W1: GasT_C_sd | X1: AmbT_C | Y1: AmbT_C_sd | Z1: RD0_us | AA1: RD0_us_sd | AB1: RD1_us | AC1: RD1_us_sd | AD1: Temp_Status_mA | AE1: Temp_Status_mA_sd | AF1: Analyzer_Status_mA | AG1: Analyzer_Status_mA_sd | AH1: Fit_Flag | AI1: MIU_VALVE | AJ1: MIU_DESC
A2: 0 | B2: 44838.453 | C2: 10/04/2022 10:52:00.689 | D2: 3.40722 | E2: 0.000780476 | F2: 81.5125 | G2: 0.0186717 | H2: 1.91945 | I2: 0.00243254 | J2: 10264.1 | K2: 97.7048 | L2: 13021.3 | M2: 120.211 | N2: 470.761 | O2: 1.24761 | P2: 1.93936 | Q2: 0.0023279 | R2: 475.643 | S2: 1.23252 | T2: 507.177 | U2: 0.0167982 | V2: 19.1523 | W2: 0.00450941 | X2: 25.3566 | Y2: 0.0189802 | Z2: 3.72081 | AA2: 0.000312849 | AB2: 3.03158 | AC2: 0.000365577 | AD2: 20 | AE2: 0 | AF2: 9 | AG2: 0 | AH2: 3 | AI2: -1 | AJ2: Disabled
A3: 5 | B3: 44838.453 | C3: 10/04/2022 10:52:05.662 | D3: 3.40584 | E3: 0.000931739 | F3: 81.4794 | G3: 0.0222904 | H3: 1.9222 | I3: 0.00259766 | J3: 10475.7 | K3: 169.919 | L3: 13094.3 | M3: 138.081 | N3: 471.755 | O3: 1.2987 | P3: 1.94255 | Q3: 0.00280884 | R3: 476.749 | S3: 1.38781 | T3: 507.158 | U3: 0.0439334 | V3: 19.1689 | W3: 0.00328128 | X3: 25.372 | Y3: 0.0185956 | Z3: 3.72003 | AA3: 0.000597215 | AB3: 3.03216 | AC3: 0.000622552 | AD3: 20 | AE3: 0 | AF3: 9 | AG3: 0 | AH3: 3 | AI3: -1 | AJ3: Disabled
A4: 10 | B4: 44838.453 | C4: 10/04/2022 10:52:10.634 | D4: 3.40526 | E4: 0.000471737 | F4: 81.4656 | G4: 0.0112856 | H4: 1.92039 | I4: 0.00295176 | J4: 10312.1 | K4: 279.527 | L4: 12921 | M4: 174.529 | N4: 473.003 | O4: 1.03416 | P4: 1.9404 | Q4: 0.0033755 | R4: 477.932 | S4: 1.14096 | T4: 507.147 | U4: 0.0427047 | V4: 19.1764 | W4: 0.00658054 | X4: 25.4045 | Y4: 0.0140326 | Z4: 3.7209 | AA4: 0.000570026 | AB4: 3.03236 | AC4: 0.000532572 | AD4: 20 | AE4: 0 | AF4: 9 | AG4: 0 | AH4: 3 | AI4: -1 | AJ4: Disabled
A5: 15 | B5: 44838.453 | C5: 10/04/2022 10:52:15.606 | D5: 3.40437 | E5: 0.00094481 | F5: 81.4443 | G5: 0.0226031 | H5: 1.9201 | I5: 0.00205498 | J5: 10575.6 | K5: 90.6738 | L5: 13140.4 | M5: 57.5343 | N5: 474.674 | O5: 1.31822 | P5: 1.94062 | Q5: 0.00193723 | R5: 479.747 | S5: 1.3043 | T5: 507.198 | U5: 0.0180773 | V5: 19.1896 | W5: 0.00204077 | X5: 25.4272 | Y5: 0.0274701 | Z5: 3.72113 | AA5: 0.000301962 | AB5: 3.03247 | AC5: 0.00024315 | AD5: 20 | AE5: 0 | AF5: 9 | AG5: 0 | AH5: 3 | AI5: -1 | AJ5: Disabled
A6: 20 | B6: 44838.453 | C6: 10/04/2022 10:52:20.581 | D6: 3.40442 | E6: 0.00107345 | F6: 81.4453 | G6: 0.0256806 | H6: 1.9204 | I6: 0.00376369 | J6: 10352.5 | K6: 271.413 | L6: 12823.6 | M6: 211.927 | N6: 478.402 | O6: 1.19571 | P6: 1.94049 | Q6: 0.00429851 | R6: 483.407 | S6: 1.31646 | T6: 507.181 | U6: 0.0419756 | V6: 19.2089 | W6: 0.00417432 | X6: 25.4375 | Y6: 0.0244171 | Z6: 3.72128 | AA6: 0.000614744 | AB6: 3.03207 | AC6: 0.000558525 | AD6: 20 | AE6: 0 | AF6: 9 | AG6: 0 | AH6: 3 | AI6: -1 | AJ6: Disabled
A7: 25 | B7: 44838.453 | C7: 10/04/2022 10:52:25.552 | D7: 3.40422 | E7: 0.000867981 | F7: 81.4406 | G7: 0.0207651 | H7: 1.92284 | I7: 0.00381755 | J7: 10311 | K7: 183.648 | L7: 12859.9 | M7: 144.568 | N7: 480.896 | O7: 0.640725 | P7: 1.94288 | Q7: 0.00379211 | R7: 485.906 | S7: 0.695733 | T7: 507.137 | U7: 0.0408333 | V7: 19.2209 | W7: 0.00379609 | X7: 25.4337 | Y7: 0.0141971 | Z7: 3.72014 | AA7: 0.00059431 | AB7: 3.03208 | AC7: 0.000346193 | AD7: 20 | AE7: 0 | AF7: 9 | AG7: 0 | AH7: 3 | AI7: -1 | AJ7: Disabled
A8: 30 | B8: 44838.453 | C8: 10/04/2022 10:52:30.526 | D8: 3.40449 | E8: 0.000989348 | F8: 81.447 | G8: 0.0236686 | H8: 1.92201 | I8: 0.00301547 | J8: 10351.5 | K8: 130.199 | L8: 13002.4 | M8: 66.8474 | N8: 482.501 | O8: 0.705447 | P8: 1.94212 | Q8: 0.00280006 | R8: 487.548 | S8: 0.70965 | T8: 507.17 | U8: 0.0455922 | V8: 19.2294 | W8: 0.00524611 | X8: 25.4401 | Y8: 0.0126384 | Z8: 3.72112 | AA8: 0.000380849 | AB8: 3.03246 | AC8: 0.000493636 | AD8: 20 | AE8: 0 | AF8: 9 | AG8: 0 | AH8: 3 | AI8: -1 | AJ8: Disabled
A9: 35 | B9: 44838.453 | C9: 10/04/2022 10:52:35.498 | D9: 3.40462 | E9: 0.00114902 | F9: 81.4503 | G9: 0.0274886 | H9: 1.92073 | I9: 0.0020964 | J9: 10234.6 | K9: 195.815 | L9: 12833.2 | M9: 197.265 | N9: 485.29 | O9: 2.10378 | P9: 1.94059 | Q9: 0.00200397 | R9: 490.308 | S9: 2.0809 | T9: 507.163 | U9: 0.024297 | V9: 19.2429 | W9: 0.00341129 | X9: 25.4365 | Y9: 0.0212338 | Z9: 3.72073 | AA9: 0.000517004 | AB9: 3.03225 | AC9: 0.000346623 | AD9: 20 | AE9: 0 | AF9: 9 | AG9: 0 | AH9: 3 | AI9: -1 | AJ9: Disabled
A10: 40 | B10: 44838.453 | C10: 10/04/2022 10:52:40.471 | D10: 3.40483 | E10: 0.000255419 | F10: 81.4552 | G10: 0.00611051 | H10: 1.92209 | I10: 0.00239349 | J10: 10300.6 | K10: 210.926 | L10: 12810.9 | M10: 258.036 | N10: 488.502 | O10: 1.41518 | P10: 1.9421 | Q10: 0.00233552 | R10: 493.586 | S10: 1.39204 | T10: 507.114 | U10: 0.0176463 | V10: 19.2555 | W10: 0.00466748 | X10: 25.4567 | Y10: 0.0215855 | Z10: 3.72133 | AA10: 0.000527913 | AB10: 3.03245 | AC10: 0.000495367 | AD10: 20 | AE10: 0 | AF10: 9 | AG10: 0 | AH10: 3 | AI10: -1 | AJ10: Disabled
A11: 45 | B11: 44838.453 | C11: 10/04/2022 10:52:45.443 | D11: 3.40498 | E11: 0.00106626 | F11: 81.4589 | G11: 0.0255085 | H11: 1.92327 | I11: 0.00227915 | J11: 10623.9 | K11: 333.414 | L11: 13010.7 | M11: 156.692 | N11: 491.5 | O11: 0.664814 | P11: 1.94393 | Q11: 0.00196551 | R11: 496.778 | S11: 0.714402 | T11: 507.147 | U11: 0.0214997 | V11: 19.2689 | W11: 0.003963 | X11: 25.4719 | Y11: 0.0324897 | Z11: 3.72179 | AA11: 0.000459169 | AB11: 3.03256 | AC11: 0.000405606 | AD11: 20 | AE11: 0 | AF11: 9 | AG11: 0 | AH11: 3 | AI11: -1 | AJ11: Disabled
A12: 50 | B12: 44838.453 | C12: 10/04/2022 10:52:50.415 | D12: 3.40569 | E12: 0.00104926 | F12: 81.4757 | G12: 0.0251019 | H12: 1.92453 | I12: 0.00347437 | J12: 10331.3 | K12: 116.875 | L12: 12776 | M12: 99.1334 | N12: 493.503 | O12: 1.39569 | P12: 1.94462 | Q12: 0.00343258 | R12: 498.655 | S12: 1.3534 | T12: 507.174 | U12: 0.0285637 | V12: 19.2822 | W12: 0.00252823 | X12: 25.4719 | Y12: 0.0145302 | Z12: 3.72194 | AA12: 0.000627814 | AB12: 3.03304 | AC12: 0.000514802 | AD12: 20 | AE12: 0 | AF12: 9 | AG12: 0 | AH12: 3 | AI12: -1 | AJ12: Disabled
A13: 55 | B13: 44838.453 | C13: 10/04/2022 10:52:55.389 | D13: 3.4049 | E13: 0.00121672 | F13: 81.4569 | G13: 0.0291081 | H13: 1.92359 | I13: 0.0036915 | J13: 10405 | K13: 59.0296 | L13: 12834.3 | M13: 145.46 | N13: 495.821 | O13: 1.90785 | P13: 1.94382 | Q13: 0.00383015 | R13: 501.034 | S13: 1.91117 | T13: 507.124 | U13: 0.0355665 | V13: 19.2944 | W13: 0.00586631 | X13: 25.4967 | Y13: 0.0307177 | Z13: 3.72277 | AA13: 0.000333837 | AB13: 3.03335 | AC13: 0.000341662 | AD13: 20 | AE13: 0 | AF13: 9 | AG13: 0 | AH13: 3 | AI13: -1 | AJ13: Disabled
... A215: 1065 | B215: 44838.465 | C215: 10/04/2022 11:09:39.987 | D215: 3.34061 | E215: 0.00136098 | F215: 79.9189 | G215: 0.0325593 | H215: 1.95654 | I215: 0.0023952 | J215: 10845.5 | K215: 129.089 | L215: 13550.8 | M215: 165.374 | N215: 951.962 | O215: 1.41017 | P215: 1.97799 | Q215: 0.00236962 | R215: 962.399 | S215: 1.50524 | T215: 506.998 | U215: 0.0336427 | V215: 21.5626 | W215: 0.00465417 | X215: 27.212 | Y215: 0.016076 | Z215: 3.72183 | AA215: 0.000727557 | AB215: 3.03159 | AC215: 0.000304079 | AD215: 20 | AE215: 0 | AF215: 9 | AG215: 0 | AH215: 3 | AI215: -1 | AJ215: Disabled

Sheet 600cm
A1: Seconds | B1: SysTime | C1: Time | D1: Batt_v | E1: Batt_v_sd | F1: BATT_PERCENT | G1: BATT_PERCENT_sd | H1: [CH4]_ppm | I1: [CH4]_ppm_sd | J1: [H2O]_ppm | K1: [H2O]_ppm_sd | L1: [H2Oa]_ppm | M1: [H2Oa]_ppm_sd | N1: [CO2]_ppm | O1: [CO2]_ppm_sd | P1: [CH4]d_ppm | Q1: [CH4]d_ppm_sd | R1: [CO2]d_ppm | S1: [CO2]d_ppm_sd | T1: GasP_torr | U1: GasP_torr_sd | V1: GasT_C | W1: GasT_C_sd | X1: AmbT_C | Y1: AmbT_C_sd | Z1: RD0_us | AA1: RD0_us_sd | AB1: RD1_us | AC1: RD1_us_sd | AD1: Temp_Status_mA | AE1: Temp_Status_mA_sd | AF1: Analyzer_Status_mA | AG1: Analyzer_Status_mA_sd | AH1: Fit_Flag | AI1: MIU_VALVE | AJ1: MIU_DESC
A2: 0 | B2: 44838.472 | C2: 10/04/2022 11:19:01.948 | D2: 3.29725 | E2: 0.00464495 | F2: 78.8816 | G2: 0.111123 | H2: 1.92327 | I2: 0.00127391 | J2: 11867.7 | K2: 84.9159 | L2: 14266.4 | M2: 75.4219 | N2: 454.138 | O2: 1.00744 | P2: 1.94637 | Q2: 0.00126544 | R2: 459.592 | S2: 1.00112 | T2: 506.93 | U2: 0.0464483 | V2: 22.6039 | W2: 0.00312993 | X2: 27.7165 | Y2: 0.0246948 | Z2: 3.724 | AA2: 0.000361889 | AB2: 3.03128 | AC2: 0.000223091 | AD2: 20 | AE2: 0 | AF2: 9 | AG2: 0 | AH2: 3 | AI2: -1 | AJ2: Disabled
A3: 5 | B3: 44838.472 | C3: 10/04/2022 11:19:06.921 | D3: 3.29832 | E3: 0.00317793 | F3: 78.9071 | G3: 0.0760271 | H3: 1.92577 | I3: 0.00289824 | J3: 11762 | K3: 164.408 | L3: 14198.6 | M3: 81.8257 | N3: 456.624 | O3: 1.4368 | P3: 1.94869 | Q3: 0.00311709 | R3: 462.059 | S3: 1.42737 | T3: 506.929 | U3: 0.05129 | V3: 22.6116 | W3: 0.00743253 | X3: 27.7248 | Y3: 0.0289787 | Z3: 3.72377 | AA3: 0.000478101 | AB3: 3.0309 | AC3: 0.000193956 | AD3: 20 | AE3: 0 | AF3: 9 | AG3: 0 | AH3: 3 | AI3: -1 | AJ3: Disabled
A4: 10 | B4: 44838.472 | C4: 10/04/2022 11:19:11.894 | D4: 3.29768 | E4: 0.003273 | F4: 78.8919 | G4: 0.0783014 | H4: 1.92434 | I4: 0.00284061 | J4: 11686.8 | K4: 180.192 | L4: 14037.8 | M4: 243.222 | N4: 457.398 | O4: 1.24532 | P4: 1.9471 | Q4: 0.00260646 | R4: 462.807 | S4: 1.33821 | T4: 506.921 | U4: 0.0323442 | V4: 22.6202 | W4: 0.00474488 | X4: 27.7133 | Y4: 0.0235818 | Z4: 3.72392 | AA4: 0.000594034 | AB4: 3.03105 | AC4: 0.000452504 | AD4: 20 | AE4: 0 | AF4: 9 | AG4: 0 | AH4: 3 | AI4: -1 | AJ4: Disabled
A5: 15 | B5: 44838.472 | C5: 10/04/2022 11:19:16.866 | D5: 3.29559 | E5: 0.00403183 | F5: 78.8419 | G5: 0.0964552 | H5: 1.92092 | I5: 0.00212106 | J5: 11890.2 | K5: 131.885 | L5: 14224.4 | M5: 143.52 | N5: 459.393 | O5: 1.4491 | P5: 1.94404 | Q5: 0.00233827 | R5: 464.921 | S5: 1.52256 | T5: 506.955 | U5: 0.0563369 | V5: 22.6289 | W5: 0.00720723 | X5: 27.7365 | Y5: 0.0104717 | Z5: 3.72367 | AA5: 0.000481284 | AB5: 3.03154 | AC5: 0.000403813 | AD5: 20 | AE5: 0 | AF5: 9 | AG5: 0 | AH5: 3 | AI5: -1 | AJ5: Disabled
A6: 20 | B6: 44838.472 | C6: 10/04/2022 11:19:21.839 | D6: 3.29928 | E6: 0.00410379 | F6: 78.9301 | G6: 0.0981768 | H6: 1.9234 | I6: 0.00166896 | J6: 12022.2 | K6: 157.812 | L6: 14290.2 | M6: 210.566 | N6: 462.031 | O6: 1.09528 | P6: 1.9468 | Q6: 0.00190951 | R6: 467.654 | S6: 1.15501 | T6: 506.912 | U6: 0.0340444 | V6: 22.6318 | W6: 0.00726931 | X6: 27.7309 | Y6: 0.0125502 | Z6: 3.72317 | AA6: 0.000576779 | AB6: 3.03181 | AC6: 0.000261616 | AD6: 20 | AE6: 0 | AF6: 9 | AG6: 0 | AH6: 3 | AI6: -1 | AJ6: Disabled
A7: 25 | B7: 44838.472 | C7: 10/04/2022 11:19:26.812 | D7: 3.30288 | E7: 0.000837721 | F7: 79.0162 | G7: 0.0200412 | H7: 1.92335 | I7: 0.002543 | J7: 11941.8 | K7: 138.448 | L7: 14291 | M7: 124.792 | N7: 463.492 | O7: 0.519746 | P7: 1.9466 | Q7: 0.00254464 | R7: 469.094 | S7: 0.58172 | T7: 506.952 | U7: 0.0533823 | V7: 22.6417 | W7: 0.00222148 | X7: 27.7422 | Y7: 0.0316914 | Z7: 3.72338 | AA7: 0.000424348 | AB7: 3.03188 | AC7: 0.000152122 | AD7: 20 | AE7: 0 | AF7: 9 | AG7: 0 | AH7: 3 | AI7: -1 | AJ7: Disabled
A8: 30 | B8: 44838.472 | C8: 10/04/2022 11:19:31.785 | D8: 3.2982 | E8: 0.00268881 | F8: 78.9043 | G8: 0.0643256 | H8: 1.92516 | I8: 0.00201936 | J8: 11889.2 | K8: 85.2704 | L8: 14231.8 | M8: 125.642 | N8: 465.177 | O8: 1.0063 | P8: 1.94832 | Q8: 0.00215056 | R8: 470.774 | S8: 1.01564 | T8: 506.891 | U8: 0.0508004 | V8: 22.654 | W8: 0.00518919 | X8: 27.7469 | Y8: 0.0385998 | Z8: 3.72419 | AA8: 0.000796529 | AB8: 3.03159 | AC8: 0.000426045 | AD8: 20 | AE8: 0 | AF8: 9 | AG8: 0 | AH8: 3 | AI8: -1 | AJ8: Disabled
A9: 35 | B9: 44838.472 | C9: 10/04/2022 11:19:36.758 | D9: 3.29553 | E9: 0.00281927 | F9: 78.8404 | G9: 0.0674466 | H9: 1.92335 | I9: 0.00102985 | J9: 11834.2 | K9: 222.264 | L9: 14293.1 | M9: 72.5757 | N9: 467.041 | O9: 0.833643 | P9: 1.94638 | Q9: 0.00127179 | R9: 472.635 | S9: 0.835631 | T9: 506.881 | U9: 0.044024 | V9: 22.6505 | W9: 0.00277841 | X9: 27.7495 | Y9: 0.0318881 | Z9: 3.72441 | AA9: 0.000270035 | AB9: 3.03137 | AC9: 0.000290447 | AD9: 20 | AE9: 0 | AF9: 9 | AG9: 0 | AH9: 3 | AI9: -1 | AJ9: Disabled
A10: 40 | B10: 44838.472 | C10: 10/04/2022 11:19:41.730 | D10: 3.29239 | E10: 0.000433209 | F10: 78.7652 | G10: 0.0103639 | H10: 1.92252 | I10: 0.00202841 | J10: 11921.9 | K10: 91.3457 | L10: 14226.4 | M10: 163.371 | N10: 468.053 | O10: 1.37835 | P10: 1.94572 | Q10: 0.00208432 | R10: 473.7 | S10: 1.39913 | T10: 506.922 | U10: 0.0757431 | V10: 22.6625 | W10: 0.00756882 | X10: 27.7308 | Y10: 0.0268194 | Z10: 3.724 | AA10: 0.000291394 | AB10: 3.0314 | AC10: 0.000123369 | AD10: 20 | AE10: 0 | AF10: 9 | AG10: 0 | AH10: 3 | AI10: -1 | AJ10: Disabled
A11: 45 | B11: 44838.472 | C11: 10/04/2022 11:19:46.704 | D11: 3.29291 | E11: 0.00263763 | F11: 78.7777 | G11: 0.0631011 | H11: 1.92495 | I11: 0.0037098 | J11: 11868.4 | K11: 200.819 | L11: 14290.1 | M11: 52.6644 | N11: 471.096 | O11: 1.63577 | P11: 1.94807 | Q11: 0.00387994 | R11: 476.754 | S11: 1.61894 | T11: 506.885 | U11: 0.0658486 | V11: 22.6692 | W11: 0.00354261 | X11: 27.7369 | Y11: 0.0180621 | Z11: 3.72418 | AA11: 0.000567119 | AB11: 3.03132 | AC11: 0.00021133 | AD11: 20 | AE11: 0 | AF11: 9 | AG11: 0 | AH11: 3 | AI11: -1 | AJ11: Disabled
A12: 50 | B12: 44838.472 | C12: 10/04/2022 11:19:51.682 | D12: 3.29974 | E12: 0.000953009 | F12: 78.9413 | G12: 0.0227993 | H12: 1.92437 | I12: 0.00125566 | J12: 11832.3 | K12: 99.9093 | L12: 14256.1 | M12: 89.7924 | N12: 471.967 | O12: 0.701038 | P12: 1.94741 | Q12: 0.0011563 | R12: 477.618 | S12: 0.749902 | T12: 506.92 | U12: 0.0616595 | V12: 22.678 | W12: 0.00543415 | X12: 27.748 | Y12: 0.0210722 | Z12: 3.7244 | AA12: 0.000412524 | AB12: 3.03169 | AC12: 0.000351017 | AD12: 20 | AE12: 0 | AF12: 9 | AG12: 0 | AH12: 3 | AI12: -1 | AJ12: Disabled
A13: 55 | B13: 44838.472 | C13: 10/04/2022 11:19:56.657 | D13: 3.30262 | E13: 0.00274493 | F13: 79.0099 | G13: 0.0656682 | H13: 1.92251 | I13: 0.00273316 | J13: 11953.8 | K13: 130.877 | L13: 14214.1 | M13: 143.532 | N13: 475.743 | O13: 1.08143 | P13: 1.94577 | Q13: 0.0028073 | R13: 481.498 | S13: 1.06772 | T13: 506.869 | U13: 0.0463122 | V13: 22.6768 | W13: 0.00510562 | X13: 27.759 | Y13: 0.0145293 | Z13: 3.72422 | AA13: 0.000629925 | AB13: 3.03189 | AC13: 0.000102748 | AD13: 20 | AE13: 0 | AF13: 9 | AG13: 0 | AH13: 3 | AI13: -1 | AJ13: Disabled
